2022-10-03 15:06:59,621 - urllib3.connectionpool - DEBUG - Starting new HTTPS connection (1): api.openweathermap.org:443
2022-10-03 15:06:59,861 - urllib3.connectionpool - DEBUG - https://api.openweathermap.org:443 "GET /data/2.5/forecast?q=magic%2Cmn&units=imperial&appid=f72d5f44278ba64d133fc40e52d34075 HTTP/1.1" 404 40
2022-10-03 15:06:59,863 - root - ERROR - Error retriving weather data 404 Client Error: Not Found for url: https://api.openweathermap.org/data/2.5/forecast?q=magic%2Cmn&units=imperial&appid=f72d5f44278ba64d133fc40e52d34075
Traceback (most recent call last):
  File "C:\Users\Nate O\Desktop\ITEC2905_Capstone_LabWork\WeekSix\LabSix\forecast_fivedays.py", line 49, in get_forecast_data
    url_response.raise_for_status() # raises HTTP error if one is occured.
  File "C:\Users\Nate O\Desktop\ITEC2905_Capstone_LabWork\WeekSix\env\lib\site-packages\requests\models.py", line 1021, in raise_for_status
    raise HTTPError(http_error_msg, response=self)
requests.exceptions.HTTPError: 404 Client Error: Not Found for url: https://api.openweathermap.org/data/2.5/forecast?q=magic%2Cmn&units=imperial&appid=f72d5f44278ba64d133fc40e52d34075
2022-10-03 15:06:59,864 - root - INFO - Url error response {"cod":"404","message":"city not found"}
2022-10-03 15:07:22,312 - urllib3.connectionpool - DEBUG - Starting new HTTPS connection (1): api.openweathermap.org:443
2022-10-03 15:07:22,617 - urllib3.connectionpool - DEBUG - https://api.openweathermap.org:443 "GET /data/2.5/forecast?q=Minneapolis%2CUS&units=metric&appid=f72d5f44278ba64d133fc40e52d34075 HTTP/1.1" 200 15846
